Workbook

Sheet Offer
G2: =IFERROR(VLOOKUP(B2,'PRICE LIST'!$B:$D,3,FALSE)/100,"")
A3: SR.NO | B3: Item Code | C3: Make | D3: Packing Quantity PCS | E3: Quantity (Customer enters) | F3: Rate (Per 100 pcs) | G3: Dis.% | H3: Net Rate/PCS | I3: Total Value
A4: =IF(B4="","",ROWS($A$4:A4)) | B4: 206-118 | C4: =IFERROR(VLOOKUP(B4,'PRICE LIST'!$B:$D,2,FALSE),"") | D4: =IFERROR(VLOOKUP(B4,'PRICE LIST'!$B:$D,2,FALSE),"") | F4: =IFERROR(VLOOKUP(B4,'PRICE LIST'!$B:$D,3,FALSE),"") | H4: =IF(OR(F4="",G4=""),"",ROUND((F4/100)*(1-G4/100),2)) | I4: =IF(OR(E4="",H4=""),"",ROUND(E4*H4,2))
A5: =IF(B5="","",ROWS($A$4:A5)) | B5: 206-804 | C5: WAGO | D5: 11 | G5: =IFERROR(VLOOKUP(B5,'PRICE LIST'!$B:$D,3,FALSE)/100,"") | I5: =D5*G5
A6: =IF(B6="","",ROWS($A$4:A6)) | B6: 206-1125 | C6: WAGO | D6: 12 | G6: =IFERROR(VLOOKUP(B6,'PRICE LIST'!$B:$D,3,FALSE)/100,"") | I6: =D6*G6
A7: =IF(B7="","",ROWS($A$4:A7)) | B7: 206-1141 | C7: WAGO | D7: 13 | G7: =IFERROR(VLOOKUP(B7,'PRICE LIST'!$B:$D,3,FALSE)/100,"") | I7: =D7*G7
A8: =IF(B8="","",ROWS($A$4:A8)) | B8: 206-1204 | C8: WAGO | D8: 14 | G8: =IFERROR(VLOOKUP(B8,'PRICE LIST'!$B:$D,3,FALSE)/100,"") | I8: =D8*G8
A9: =IF(B9="","",ROWS($A$4:A9)) | B9: 206-1216 | C9: WAGO | D9: 15 | G9: =IFERROR(VLOOKUP(B9,'PRICE LIST'!$B:$D,3,FALSE)/100,"") | I9: =D9*G9
A10: =IF(B10="","",ROWS($A$4:A10)) | B10: 206-1250 | C10: WAGO | D10: 16 | G10: =IFERROR(VLOOKUP(B10,'PRICE LIST'!$B:$D,3,FALSE)/100,"") | I10: =#REF!*G10
A11: =IF(B11="","",ROWS($A$4:A11)) | B11: 206-2101 | C11: WAGO | D11: 17 | G11: =IFERROR(VLOOKUP(B11,'PRICE LIST'!$B:$D,3,FALSE)/100,"") | I11: =#REF!*G11
A12: =IF(B12="","",ROWS($A$4:A12)) | B12: 206-2102 | C12: WAGO | D12: 18 | G12: =IFERROR(VLOOKUP(B12,'PRICE LIST'!$B:$D,3,FALSE)/100,"") | I12: =#REF!*G12
A13: =IF(B13="","",ROWS($A$4:A13)) | B13: 207-1331 | C13: WAGO | D13: 19 | G13: =IFERROR(VLOOKUP(B13,'PRICE LIST'!$B:$D,3,FALSE)/100,"") | I13: =#REF!*G13
A14: =IF(B14="","",ROWS($A$4:A14)) | B14: 207-1332 | C14: WAGO | D14: 20 | G14: =IFERROR(VLOOKUP(B14,'PRICE LIST'!$B:$D,3,FALSE)/100,"") | I14: =#REF!*G14
A15: =IF(B15="","",ROWS($A$4:A15)) | B15: 207-1333 | C15: WAGO | D15: 21 | G15: =IFERROR(VLOOKUP(B15,'PRICE LIST'!$B:$D,3,FALSE)/100,"") | I15: =#REF!*G15
A16: =IF(B16="","",ROWS($A$4:A16)) | B16: 207-1432 | C16: WAGO | D16: 22 | G16: =IFERROR(VLOOKUP(B16,'PRICE LIST'!$B:$D,3,FALSE)/100,"") | I16: =#REF!*G16
B17: 209-101
B18: 209-106
B19: 209-112
B20: 209-113
B21: 209-114
B22: 209-120
B23: 209-122
B24: 209-123
B25: 209-129
B26: 209-132
B27: 209-137
B28: 209-140
... B3322: 8002-100/1000-860

Sheet Stock Group Reorder Status
A1: PIONEER TECHNOLOGY
A2: Sai Datta Reality,Survey No 452/1/1/10,Alankapuram
A3: Road,Tapkir Nagar,Bhosari,Pune-412105
A4: UDYAM : UDYAM-MH-26-0071108 (Micro)
A5: E-Mail : rajesh@pioneerautomation.in
A6: Stock Group Reorder Status
A7: Under Group: Wago
A8: 1-Apr-26 to 29-Jul-26
A9: Item Code | B9: Closing Stock | C9: Purc Orders Pending | D9: Sale Orders Due | E9: Nett Available | F9: Re-order Level | G9: Short fall | H9: Min Reorder Qty | I9: Order to be Placed
A10: 0249-0116/0981-0008 | C10: 9000 | E10: 9000
A11: 0280-0308/0981-0008 | C11: 300 | E11: 300
A12: 0280-0314/0981-0008 | C12: 100 | E12: 100
A13: 0280-0342/0981-0008 | C13: 300 | E13: 300
A14: 0280-0402/0981-0008 | C14: 2000 | E14: 2000
A15: 0280-0520/0981-0008 | C15: 8000 | D15: 5000 | E15: 3000
A16: 0280-0833/0981-0008 | C16: 6000 | D16: 5000 | E16: 1000
A17: 0280-0901/0981-0008 | C17: 8000 | E17: 8000
A18: 0281-0328/0981-0000
A19: 0281-0328/0981-0008 | C19: 500 | E19: 500
A20: 0281-0903/0981-0000 | C20: 1000 | E20: 1000
A21: 0281-0904/0981-0000 | B21: 100 | C21: 1000 | E21: 1100
A22: 0281-0905/0981-0000 | C22: 500 | E22: 500
A23: 0281-0906/0981-0000 | C23: 1000 | E23: 1000
A24: 0281-0907/0981-0000 | C24: 500 | E24: 500
A25: 2000-1201
A26: 2000-1203
A27: 2000-1204
A28: 2000-1205
A29: 2000-1207
A30: 2000-1291
A31: 2000-1401 | C31: 100 | D31: 50 | E31: 50
A32: 2000-1491 | C32: 100 | D32: 25 | E32: 75
A33: 2000-2291 | B33: 3 | E33: 3
A34: 2000-402
A35: 2000-402/000-005
A36: 2000-402/000-006
A37: 2000-403 | C37: 7 | D37: 7
A38: 2000-406
A39: 2000-406/000-005
A40: 2000-406/000-406
...

Sheet PRICE LIST
A1: Series | B1: Item Code | C1: Packing Quantity PCS | D1: Price in " Per 100pcs
A2: 206 | B2: 206-118 | C2: 10 | D2: 720035
A3: 206 | B3: 206-804 | C3: 6 | D3: 1172073
A4: 206 | B4: 206-1125 | C4: 1 | D4: 1955425
A5: 206 | B5: 206-1141 | C5: TBC | D5: 463540
A6: 206 | B6: 206-1204 | C6: 1 | D6: 2990650
A7: 206 | B7: 206-1216 | C7: 1 | D7: 3334543
A8: 206 | B8: 206-1250 | C8: 1 | D8: 4035120
A9: 206 | B9: 206-2101 | C9: TBC | D9: 779483
A10: 206 | B10: 206-2102 | C10: TBC | D10: 779483
A11: 207 | B11: 207-1331 | C11: 48 | D11: 75358
A12: 207 | B12: 207-1332 | C12: 48 | D12: 75358
A13: 207 | B13: 207-1333 | C13: 100 | D13: 95460
A14: 207 | B14: 207-1432 | C14: 36 | D14: 104060
A15: 209 | B15: 209-101 | C15: 100 | D15: 4547
A16: 209 | B16: 209-106 | C16: 100 | D16: 2772
A17: 209 | B17: 209-112 | C17: 100 | D17: 891
A18: 209 | B18: 209-113 | C18: 100 | D18: 52030
A19: 209 | B19: 209-114 | C19: 100 | D19: 1097
A20: 209 | B20: 209-120 | C20: 100 | D20: 2075
A21: 209 | B21: 209-122 | C21: 100 | D21: 3343
A22: 209 | B22: 209-123 | C22: 100 | D22: 3053
... A166: 221 | B166: 221-2401 | C166: 600 | D166: 4408
A167: 221 | B167: 221-2421 | C167: TBC | D167: 5805
A168: 221 | B168: 221-2501 | C168: 25 | D168: 6450
A169: 221 | B169: 221-2502 | C169: 25 | D169: 6988
A170: 221 | B170: 221-2503 | C170: 25 | D170: 8063
A171: 221 | B171: 221-2504 | C171: 25 | D171: 8923
A172: 221 | B172: 221-2512 | C172: 25 | D172: 7525
A173: 221 | B173: 221-2513 | C173: 25 | D173: 8690
A174: 221 | B174: 221-2515 | C174: 25 | D174: 10213
A175: 221 | B175: 221-2521 | C175: 25 | D175: 5913
A176: 221 | B176: 221-2522 | C176: 25 | D176: 6558
A177: 221 | B177: 221-2523 | C177: 25 | D177: 7203
A178: 221 | B178: 221-2533 | C178: 25 | D178: 7525
A179: 221 | B179: 221-412 | C179: 1000 | D179: 3171
A180: 221 | B180: 221-413 | C180: 500 | D180: 4322
A181: 221 | B181: 221-413/995-012 | C181: TBC | D181: 6773
A182: 221 | B182: 221-415 | C182: 250 | D182: 7633
A183: 221 | B183: 221-415/995-000 | C183: TBC | D183: 11610
...
